Workbook

Sheet Cover
A2: CÔNG TY CỔ PHẦN CÔNG NGHỆ BLUE OCEAN BLUE OCEAN TECHNOLOGY JOINT STOCK COMPANY
A4: Tên dự án: GADEMY - TRƯỜNG HỌC ẢO GIAI ĐOẠN MVP Project Name: GADEMY-VIRTUAL SCHOOL MVP PHASE KẾ HOẠCH DỰ ÁN PROJECT PLAN
E7: Mã dự án Project code | F7: BO-GDM-MVP
E8: Mã tài liệu Document code | F8: BO-GDM-MVP_PP
E9: Phiên bản tài liệu Vesion | F9: v1.0
A12: TP. Hồ Chí Minh, ngày tháng năm 2025 Ho Chi Minh City, 2025

Sheet ROC
F2: BO-GDM-MVP_PP (v1.0) Kế hoạch dự án/Project Plan
A4: LỊCH SỬ THAY ĐỔI RECORD OF CHANGE
A6: # | B6: Ngày sửa đổi Initiated date | C6: Ngày hiệu lực Effective date | D6: Phiên bản Version | E6: Mô tả thay đổi Description of Change | F6: Lý do Reason | G6: Ghi chú Note
A7: 1 | D7: 1 | E7: Tất cả nội dung/All content | F7: Khởi tạo tài liệu/Initial release | G7: N/A
A8: 2 | D8: 2 | E8: Tất cả nội dung/All content | F8: Thay đổi về nhân sự và tính năng | G8: N/A
A10: Người biên soạn Created by | D10: Người xem xét Reviewed by | F10: Người phê duyệt Approved by
A11: Ký tên/ngày ký Sign / Date | D11: Ký tên/ngày ký Sign / Date | F11: Ký tên/ngày ký Sign / Date
A12: Họ tên/Full name Bùi Phúc Minh Tâm | D12: Họ tên/Full name Đinh Thị Tố Loan | F12: Họ tên/Full name Trần Hải Trường
A13: Chức danh/ Title Project Manager | D13: Chức danh/ Title Quality Assurance | F13: Chức danh/ Title CEO/Project Director

Sheet 1.Overview
B2: =ROC!F2
A4: I. Thuật ngữ và viết tắt/ Term and Acromyms
A6: # | B6: Ký hiệu/ Symbol | C6: Giải thích/ Explantation
A7: 1 | B7: PD (Product Director) | C7: Giám đốc phụ trách sản phẩm: quyết định định hướng sản phẩm, phân bổ ngân sách và phê duyệt nội dung theo chiến lược kinh doanh và nhu cầu của khách hàng / Product Director: Decides product direction, budget allocation, and content approval based on business strategy and client needs.
A8: 2 | B8: PdM (Product Manager) | C8: Quản lý sản phẩm: chịu trách nhiệm toàn bộ vòng đời sản phẩm, từ xác định nhu cầu khách hàng, phối hợp phát triển đến hỗ trợ kinh doanh. Đưa ra tầm nhìn sản phẩm, đảm bảo sản phẩm phù hợp với mục tiêu công ty và dẫn dắt các bộ phận liên quan. / Product Manager: Oversees the entire product lifecycle, from identifying client needs and coordinating development to supporting business goals. Provides product vision and leads cross-functional teams to ensure alignment with company objectives.
A9: 3 | B9: PjM (Project Manager) | C9: Quản lý dự án: điều phối toàn bộ dự án gia công game, theo dõi tiến độ, tối ưu nguồn lực và đảm bảo dự án hoàn thành đúng hạn, đúng chất lượng cam kết / Project Manager: Coordinates outsourced software/game projects, monitors progress, optimizes resources, and ensures timely and quality delivery.
A10: 4 | B10: GDM | C10: Tên phần mềm giáo dục Gademy / Name of educational software Gademy
A11: 5 | B11: NPC (Non-player Character) | C11: Nhân vật trong game do máy tính điều khiển (AI) / Computer-controlled game characters (AI)
A12: 6 | B12: GD (Game Designer) | C12: Nhà thiết kế trò chơi: xây dựng ý tưởng, cơ chế gameplay, hệ thống và trải nghiệm người chơi; tạo tài liệu thiết kế để hướng dẫn team phát triển thực hiện đúng theo định hướng dự án / Game Designer: Develops concepts, gameplay mechanics, systems, and player experiences; creates design documents to guide the development team in delivering on project vision.
A13: 7 | B13: PO (Product Owner) | C13: Đại diện sản phẩm: làm cầu nối giữa khách hàng và team phát triển, chịu trách nhiệm quản lý backlog, làm rõ yêu cầu và xác nhận đầu ra sản phẩm đúng mong đợi / Product Owner: Acts as the bridge between client and development team, manages the backlog, clarifies requirements, and validates deliverables to meet expectations.
A14: 8 | B14: UI/UX (UI/UX Designer) | C14: UI/UX Designer: Thiết kế giao diện và trải nghiệm người dùng: phân tích yêu cầu người dùng và tạo ra các thiết kế giao diện đảm bảo tính dễ sử dụng, hấp dẫn và tối ưu trải nghiệm người dùng cuối / UI/UX Designer: Designs interfaces and user experiences by analyzing user requirements and creating designs that ensure usability, appeal, and optimal end-user experiences.
A15: 9 | B15: AL (Artist Leader) | C15: Trưởng nhóm họa sĩ: quản lý team thiết kế 2D/3D, phân công công việc, đảm bảo chất lượng hình ảnh theo định hướng mỹ thuật và tiến độ dự án / Artist Leader: Manages the 2D/3D art team, assigns tasks, and ensures visual quality aligns with art direction and project timelines.
A16: 10 | B16: TL (Technical Leader) | C16: TL: hướng dẫn kỹ thuật cho nhóm phát triển, đảm bảo kiến trúc và công nghệ được áp dụng hiệu quả trong việc xây dựng phần mềm / Technical Leader: Leads and provides technical guidance to the development team, ensuring that architecture and technologies are effectively applied in software development.
A17: 11 | B17: QC (Quality Control) | C17: QC: phụ trách kiểm thử và đảm bảo chất lượng phần mềm, phát hiện lỗi và vấn đề trước khi phát hành sản phẩm / Quality Control: Responsible for testing and ensuring the quality of software, identifying bugs and issues before the product release.
A18: 12 | B18: QA (Quality Analyst) | C18: QA: giám sát và kiểm tra các quy trình phát triển phần mềm để đảm bảo sản phẩm cuối cùng tuân thủ các tiêu chuẩn chất lượng đã đặt ra / QA: Oversees and inspects software development processes to ensure the final product adheres to established quality standards.
A19: 13 | B19: Dev (IT Developer) | C19: Dev: thực hiện việc coding và lập trình, tạo ra các giải pháp phần mềm, và cải tiến kỹ thuật để nâng cao hiệu suất và chất lượng sản phẩm / Developer: Executes coding and programming, creates software solutions, and implements technical improvements to enhance product performance and quality.
A21: II. Mục tiêu dự án/ Project Objective
A23: 1 | B23: Mục tiêu và tổng quan sản phẩm:/ Product Overview and Objective
B24: Gademy là một phần mềm giáo dục phiêu lưu hành động nhập vai cho học sinh từ lớp 1 đến lớp 9, lấy bối cảnh là một thế giới hoạt hình trong tương lai. Phần mềm được cân bằng giữa việc học và giải trí, nhằm đạt được kết quả giáo dục mạnh mẽ và mức độ tương tác cao của người dùng. Gademy sẽ đạt được hai mục tiêu này bằng những yếu tố sau: Trải nghiệm nhập vai (Immersive world-building) - Thật sự sống trong game (truly alive inside the game), không gian sống động (vibrant environments), tự do khám phá và kết nối cảm xúc. Học mà chơi (Entertaining) - Tạo cảm giác vui vẻ (Fun makes learning addictive), Người chơi bị cuốn vào việc học và không nhận ra điều đó Cạnh tranh và thi đua lành mạnh (Competitive) - Challenges spark drive, mọi người muốn thăng cấp và chiến thắng. Tương tác với bạn bè (Social interaction) - việc học trở nên sinh động hơn cùng chia sẻ, hợp tác và vui cười trong một môi trường tương tác an toàn và được giám sát Tích hợp với AI (AI Integration) - NPC chân thực hữu ích. Luôn tự động làm mới cả NPC lẫn nhiệm vụ học tập, giúp mỗi trải nghiệm đều độc đáo
B25: - Bao gồm 2 cột mốc
B26: Cột mốc 1: Xây dựng môi trường 3D trải nghiệm ảo tương tác, cho phép học sinh khám phá, học và chơi, kết nối trực tiếp với bạn bè, nhằm hỗ trợ trường tăng tỷ lệ chuyển đổi từ quan tâm sang đăng ký nhập học.
B27: Cột mốc 2: Phát triển GDM như một nền tảng học tập kết hợp giải trí, nơi học sinh có thể vừa học, vừa chơi game, kết nối bạn bè và sáng tạo tự do, nhằm tăng hiệu quả học tập và mức độ hứng thú trong trải nghiệm học tập
A28: 2 | B28: Mục tiêu xây dựng sản phẩm trong giai đoạn MVP
B29: - Mục tiêu chính: + Giúp các trường (B2B) tăng tỷ lệ tuyển sinh thông qua việc hỗ trợ học sinh khám phá, tương tác và kết nối với nhà trường trước khi nhập học tại GDM. + Giúp học sinh (B2C) học tập hiệu quả và hứng thú hơn qua GDM nơi các em có thể vừa học, vừa chơi game, kết nối bạn bè và tự do sáng tạo theo cách của mình. - Tính năng cốt lõi: + Trải nghiệm nhập vai (Immersive world-building) - Thật sự sống trong game (truly alive inside the game), không gian sống động (vibrant environments), tự do khám phá và kết nối cảm xúc. + Học mà chơi (Entertaining) - Tạo cảm giác vui vẻ (Fun makes learning addictive), Người chơi bị cuốn vào việc học và không nhận ra điều đó + Cạnh tranh và thi đua lành mạnh (Competitive) - Challenges spark drive, mọi người muốn thăng cấp và chiến thắng. + Tương tác với bạn bè (Social interaction) - việc học trở nên sinh động hơn cùng chia sẻ, hợp tác và vui cười trong một môi trường tương tác an toàn và được giám sát + Tích hợp với AI (AI Integration) - NPC chân thực hữu ích. Luôn tự động làm mới cả NPC lẫn nhiệm vụ học tập, giúp mỗi trải nghiệm đều độc đáo
A32: III. Phạm vi dự án/ Project Scope
A33: III.1 | B33: Phạm vi dự án giai đoạn MVP/ Project Scope MVP Phase
A34: 0. Nghiên cứu và Lên kế hoạch các chức năng cho giai đoạn MVP từ ngày 13/10/2025 đến hết ngày 23/11/2025
A35: 1. Milestone 1: Hoàn thiện cột mốc T3 từ ngày 24/11/2025 đến hết ngày 23/02/2026
A36: - Giao diện mới thu hút học sinh + Thế giới 3D với giao diện mới hấp dẫn - Nâng cao tương tác xã hội + Trao đổi trực tuyến với các học sinh khác - Hoạt động học - chơi liền mạch + Các gameplay mang tính thi đua và cộng tác + Mô hình trường học ảo + Lớp học trực tuyến + Khám phá các chương trình học tập trong tập đoàn
A37: 2. Milestone 2: Hoàn thiện cột mốc T5 từ ngày 24/02/2026 đến hết ngày 22/05/2026
A38: - Nâng cao sự gắn kết giữa học – chơi + AI NPCs hỗ trợ học tập + Hệ thống mission, challenge và phần thưởng động lực. - Tự do bộc lộ phong cách cá nhân và kết nối xã hội + Khu vực nhà riêng và avatar cá nhân hóa - Xây dựng cộng đồng an toàn và tích cực + AI NPCs tư vấn tâm lý + Các tính năng bổ trợ khuyến khích tương tác tích cực
A39: 3. Thực hiện UAT và Launching từ ngày 23/05/2026 đến hết ngày 01/06/2026
A40: IV. Sản phẩm bàn giao dự án/ Project Deliverables
B42: Sản phẩm | C42: Thời gian bàn giao
B43: Kế hoạch dự án | C43: 45978
B44: Đề xuất chi phí dự án | C44: 45978
B45: Danh sách lưu trữ các tính năng (Product Backlog) | C45: 45978
B46: Game Concept Document | C46: 46173
B47: Game Design Document | C47: 46173
B48: Game Asset List | C48: 46173
...

Sheet 2.Master Schedule
B2: KẾ HOẠCH TỔNG THỂ/ MASTER SCHEDULE | S2: =ROC!F2
E4: M10/25 | H4: M11/25 | L4: M12/25 | Q4: M1/26 | U4: M2/26 | Y4: M3/26 | AD4: M4/26 | AH4: M5/26 | AL4: M6/26
A5: # | B5: Epic | C5: Start Date | D5: End Date | E5: W1 | F5: W2 | G5: W3 | H5: W4 | I5: W5 | J5: W6 | K5: W7 | L5: W8 | M5: W9 | N5: W10 | O5: W11 | P5: W12 | Q5: W13 | R5: W14 | S5: W15 | T5: W16 | U5: W17 | V5: W18 | W5: W19 | X5: W20 | Y5: W21 | Z5: W22 | AA5: W23 | AB5: W24 | AC5: W25 | AD5: W26 | AE5: W27 | AF5: W28 | AG5: W29 | AH5: W30 | AI5: W31 | AJ5: W32 | AK5: W33 | AL5: W34
E6: {=DATE(2025,10,6) + (COLUMN(B1:AM1)-1)*7} | F6: 45950 | G6: 45957 | H6: 45964 | I6: 45971 | J6: 45978 | K6: 45985 | L6: 45992 | M6: 45999 | N6: 46006 | O6: 46013 | P6: 46020 | Q6: 46027 | R6: 46034 | S6: 46041 | T6: 46048 | U6: 46055 | V6: 46062 | W6: 46069 | X6: 46076 | Y6: 46083 | Z6: 46090 | AA6: 46097 | AB6: 46104 | AC6: 46111 | AD6: 46118 | AE6: 46125 | AF6: 46132 | AG6: 46139 | AH6: 46146 | AI6: 46153 | AJ6: 46160 | AK6: 46167 | AL6: 46174 | AM6: 46181 | AN6: 46188 | AO6: 46195 | AP6: 46202
A7: 1 | B7: Researching & Planning | C7: 45943 | D7: 45984
A8: 1.1 | B8: Project Plan, Product Backlog, Master Feature List | C8: 45943 | D8: 45984
A9: 1.2 | B9: Detailed Cost Plan | C9: 45943 | D9: 45984
A10: 1.3 | B10: User Journey Map for key personas | C10: 45943 | D10: 45984
A11: 1.4 | B11: Complete, approved feature list | C11: 45943 | D11: 45984
A12: 1.5 | B12: Define Game Design Document | C12: 45943 | D12: 45984
A13: 2.1 | B13: Milestone 1: Prototype | C13: 45985 | D13: 46122
A14: 2.1.1 | B14: Sprint 1 | C14: 45985 | D14: 45996
A15: 2.1.1.1 | B15: Login screen & Auth Integration | C15: 45985 | D15: 45996
A16: 2.1.2 | B16: Sprint 2 | C16: 45999 | D16: 46010
A17: 2.1.2.1 | B17: Sign up screen & Forgot Password Flow | C17: 45999 | D17: 46010
A18: 2.1.3 | B18: Sprint 3 | C18: 46013 | D18: 46024
A19: 2.1.3.1 | B19: Gademy island tutorial FTUE | C19: 46013 | D19: 46024
A20: 2.1.4 | B20: Sprint 4 | C20: 46027 | D20: 46038
A21: 2.1.4.1 | B21: School Hub island tutorial FTUE | C21: 46027 | D21: 46038
A22: 2.1.5 | B22: Sprint 5 | C22: 46041 | D22: 46052
A23: 2.1.5.1 | B23: Avatar island tutorial FTUE | C23: 46041 | D23: 46052
A24: 2.1.6 | B24: Sprint 6 | C24: 46055 | D24: 46066
... A88: 2.4.8.1 | B88: Global: Final Security & LiveOps Setup | C88: 46475 | D88: 46486

Sheet 3.Detail Schedule
A2: KẾ HOẠCH CHI TIẾT/ DETAIL SCHEDULE
A3: Task ID | B3: Task | C3: Role | D3: Start Date | E3: End Date | F3: Effort Đề Xuất (MM)
A4: 1 | B4: Milestone 0 | D4: ='2.Master Schedule'!C7 | E4: ='2.Master Schedule'!D7 | F4: =F5
A5: 1.1 | B5: Researching & Planning | D5: ='2.Master Schedule'!C7 | E5: ='2.Master Schedule'!D7 | F5: =SUM(F6:F16)
A6: 1.1.1 | B6: Define project goals, strategic direction, and approve overall scope for the upcoming phases | C6: Project Director | D6: ='2.Master Schedule'!C16 | E6: ='2.Master Schedule'!D16 | F6: =IFERROR(__xludf.DUMMYFUNCTION("(E$5-D$5) * QUERY( '4.Resource'!C:D, ""SELECT SUM(Col2) WHERE Col1 CONTAINS '"" & C6 & ""' LABEL SUM(Col2) ''"", 0 ) / 22"),0.03727272727272728)
A7: 1.1.2 | B7: Provide expert consultation on product vision, stakeholder alignment, and high-level decision-making | C7: Project Advisor | D7: ='2.Master Schedule'!C17 | E7: ='2.Master Schedule'!D17 | F7: =IFERROR(__xludf.DUMMYFUNCTION("(E$5-D$5) * QUERY( '4.Resource'!C:D, ""SELECT SUM(Col2) WHERE Col1 CONTAINS '"" & C7 & ""' LABEL SUM(Col2) ''"", 0 ) / 22"),0.2981818181818182)
A8: 1.1.3 | B8: Develop product vision, value proposition, and high-level roadmap aligned with business objectives | C8: Product Manager | D8: ='2.Master Schedule'!C18 | E8: ='2.Master Schedule'!D18 | F8: =IFERROR(__xludf.DUMMYFUNCTION("(E$5-D$5) * QUERY( '4.Resource'!C:D, ""SELECT SUM(Col2) WHERE Col1 CONTAINS '"" & C8 & ""' LABEL SUM(Col2) ''"", 0 ) / 22"),0.6709090909090909)
A9: 1.1.4 | B9: Build master plan, WBS, risk assessment, and define the project management framework | C9: Project Manager | D9: ='2.Master Schedule'!C19 | E9: ='2.Master Schedule'!D19 | F9: =IFERROR(__xludf.DUMMYFUNCTION("(E$5-D$5) * QUERY( '4.Resource'!C:D, ""SELECT SUM(Col2) WHERE Col1 CONTAINS '"" & C9 & ""' LABEL SUM(Col2) ''"", 0 ) / 22"),0.9318181818181818)
A10: 1.1.5 | B10: Assess system architecture direction, define technical boundaries, and validate feasibility of core features | C10: Technical Director | D10: ='2.Master Schedule'!C21 | E10: ='2.Master Schedule'!D21 | F10: =IFERROR(__xludf.DUMMYFUNCTION("(E$5-D$5) * QUERY( '4.Resource'!C:D, ""SELECT SUM(Col2) WHERE Col1 CONTAINS '"" & C10 & ""' LABEL SUM(Col2) ''"", 0 ) / 22"),0.0931818181818182)
A11: 1.1.6 | B11: Create and prioritize the initial product backlog, define acceptance criteria for key features | C11: Product Owner | D11: ='2.Master Schedule'!C22 | E11: ='2.Master Schedule'!D22 | F11: =IFERROR(__xludf.DUMMYFUNCTION("(E$5-D$5) * QUERY( '4.Resource'!C:D, ""SELECT SUM(Col2) WHERE Col1 CONTAINS '"" & C11 & ""' LABEL SUM(Col2) ''"", 0 ) / 22"),0.3727272727272728)
A12: 1.1.7 | B12: Support coordination activities, document meetings, organize project materials and repository structure | C12: Project Assistant | D12: ='2.Master Schedule'!C24 | E12: ='2.Master Schedule'!D24 | F12: =IFERROR(__xludf.DUMMYFUNCTION("(E$5-D$5) * QUERY( '4.Resource'!C:D, ""SELECT SUM(Col2) WHERE Col1 CONTAINS '"" & C12 & ""' LABEL SUM(Col2) ''"", 0 ) / 22"),0.3727272727272728)
A13: 1.1.8 | B13: Define the core gameplay concept, user motivation loops, and draft initial GDD structure | C13: Game Designer | D13: ='2.Master Schedule'!C25 | E13: ='2.Master Schedule'!D25 | F13: =IFERROR(__xludf.DUMMYFUNCTION("(E$5-D$5) * QUERY( '4.Resource'!C:D, ""SELECT SUM(Col2) WHERE Col1 CONTAINS '"" & C13 & ""' LABEL SUM(Col2) ''"", 0 ) / 22"),3.727272727272727)
A14: 1.1.9 | B14: Establish visual style direction, produce preliminary art guidelines, and align concept art direction | C14: Game Artist Leader | D14: ='2.Master Schedule'!C26 | E14: ='2.Master Schedule'!D26 | F14: =IFERROR(__xludf.DUMMYFUNCTION("(E$5-D$5) * QUERY( '4.Resource'!C:D, ""SELECT SUM(Col2) WHERE Col1 CONTAINS '"" & C14 & ""' LABEL SUM(Col2) ''"", 0 ) / 22"),0.9318181818181818)
A15: 1.1.10 | B15: Evaluate technical risks, define proof-of-concept needs, and support architectural decision-making | C15: Technical Leader | D15: ='2.Master Schedule'!C28 | E15: ='2.Master Schedule'!D28 | F15: =IFERROR(__xludf.DUMMYFUNCTION("(E$5-D$5) * QUERY( '4.Resource'!C:D, ""SELECT SUM(Col2) WHERE Col1 CONTAINS '"" & C15 & ""' LABEL SUM(Col2) ''"", 0 ) / 22"),0.1863636363636364)
A16: 1.1.11 | B16: Establish QA strategy, define test approach, and prepare initial test plan templates for the project | C16: Quality Assurance | D16: ='2.Master Schedule'!C29 | E16: ='2.Master Schedule'!D29 | F16: =IFERROR(__xludf.DUMMYFUNCTION("(E$5-D$5) * QUERY( '4.Resource'!C:D, ""SELECT SUM(Col2) WHERE Col1 CONTAINS '"" & C16 & ""' LABEL SUM(Col2) ''"", 0 ) / 22"),0.3727272727272728)
A17: 2 | B17: Milestone 1 | D17: ='2.Master Schedule'!C14 | E17: ='2.Master Schedule'!D14 | F17: =SUM(F18:F56)

Sheet 4.Resource
C2: KẾ HOẠCH QUẢN LÝ NGUỒN LỰC/ RESOURCE MANAGEMENT PLAN | J2: =ROC!F2
A4: Sơ đồ tổ chức dự án/ Project Org Chart
A45: Danh sách thành viên dự án/ Project Team
A54: # | B54: Họ tên / Full Name | C54: Vai trò / Role | D54: RA Đề Xuất Proposed RA (%) | E54: RA Thực Tế Actual RA (%) | F54: Kế hoạch / Plan | H54: Khối lượng / Effort (MM) | J54: Ghi chú / Note
F55: Ngày bắt đầu / Start Date | G55: Ngày kết thúc / End Date | H55: Đề Xuất / Proposed | I55: Thực Tế / Actual
A56: PMO group

Sheet 5.RiskIssue
C2: KẾ HOẠCH QUẢN LÝ RỦI RO & VẤN ĐỀ/ RISKS & ISSUES MANAGEMENT PLAN | J2: =ROC!F2
A4: Quản lý rủi ro/ Risks Management
A6: # | B6: Mức độ / Level | C6: Giai đoạn / Stage | D6: Mô tả rủi ro / Risk Description | F6: Hành động / Action | H6: Phân công cho / Assigned to | I6: Phân loại / Category | J6: Trạng thái / Status | K6: Ghi chú / Note
A7: 1 | B7: High | C7: MVP | D7: Bảo mật thông tin dự án, các tài liệu chia sẽ, site testing hệ thống. | F7: - Thực hiện ký bảo mật thông tin với các members dự án - Thực hiện giới hạn phân quyền chia sẻ tài liệu chỉ cho những member liên quan dự án - Thực hiện bảo mật các site testing và demo chỉ cho phép truy cập trong mạng nội bộ. | H7: Bùi Phúc Minh Tâm | I7: Resource | J7: In-Progress
A8: 2 | B8: High | C8: MVP | D8: Một số vị trí inhouse đang khá mỏng, gồm: - Unity, Art/2D/3D, Technical Artist | F8: Thực hiện book oursource và kết hợp với tuyển dụng dần cho những vị trí Key | H8: Bùi Phúc Minh Tâm | I8: Resource | J8: In-Progress
A9: 3 | B9: High | C9: MVP | D9: Tính kế thừa: - Chỉ giữ lại concept và ý tưởng từ giai đoạn trước. | F9: Thực hiện đánh giá và làm mới hoàn toàn: - Viết lại từ nội dung Game Design. - Tái cấu trúc base code Unity và viết mới. - Xây dựng lại CMS mới hoàn toàn | H9: Bùi Phúc Minh Tâm | I9: Resource | J9: In-Progress | K9: Dựa trên kế hoạch thực hiện của dự án
A11: Quản lý vấn đề / Issues Management
A13: # | B13: Mức độ / Level | C13: Ngày / Date | D13: Mô tả vấn đề / Issue Description | F13: Hành động / Action | H13: Phân công cho / Assigned to | I13: Hạn cuối / Deadline | J13: Trạng thái / Status | K13: Ghi chú / Note
A14: 1 | B14: Medium | C14: N/A | I14: N/A | K14: N/A
A16: Khác / Others
A18: Vui lòng lưu ý bất kỳ vấn đề nào khác mà bạn muốn báo cáo ở đây / Please note any other matters that you want to report here.

Sheet 6.CM
C2: KẾ HOẠCH QUẢN LÝ CẤU HÌNH/ CONFIGURATION MANAGEMENT PLAN | J2: =ROC!F2
A4: 1. Cơ sở hạ tầng dự án / Project Infrastructure
A5: Môi trường / Enviroment
A6: # | B6: Tên / Name | C6: Mô tả / Description | F6: Mục đích / Purpose | H6: Sở hữu / Owner | I6: Link
A7: 1 | B7: Dev | C7: Môi trường test local | F7: Test cục bộ
A8: 2 | B8: Test | C8: Môi trường test cloud | F8: Test nội bộ BO
A9: 3 | B9: Staging | C9: Môi trường chạy thử nghiệm | F9: Client UAT
A10: 4 | B10: Product | C10: Môi trường chạy chính thức | F10: Official release
A12: Phần mềm / Software
A13: # | B13: Tên / Name | C13: Mô tả / Description | F13: Mục đích / Purpose | H13: Liên kết bởi / Liencsed by | I13: Link
A14: Phát triển / For Development
A15: 1 | B15: Unity | C15: Nền tảng phát triển game đa nền tảng | F15: Xây dựng game client cho dự án
A16: 2 | B16: Visual Studio | C16: Môi trường phát triển tích hợp (IDE) | F16: Lập trình logic cho game client và dựng môi trường local cho backend
A17: 3 | B17: Visual Studio Code | C17: Trình soạn thảo mã nguồn tích hợp (IDE text editor) | F17: Viết mã nguồn cho hệ thống CMS, backend
A18: 4 | B18: MySQL Workbench | C18: GUI quản lý cơ sở dữ liệu MySQL | F18: Thiết kế, quản lý và truy vấn cơ sở dữ liệu
A19: 5 | B19: Git | C19: Hệ thống quản lý phiên bản mã nguồn phân tán | F19: Theo dõi lịch sử thay đổi mã, làm việc nhóm
A20: 6 | B20: Docker | C20: Nền tảng container hóa để triển khai ứng dụng một cách cô lập | F20: Đóng gói và triển khai ứng dụng nhất quán trên nhiều môi trường
A21: 7 | B21: API Key GPT | C21: Key sử dụng API của Open Platform API | F21: Tích hợp AI vào dự án
A23: Kiểm tra / For Test
A24: 1 | B24: Postman | C24: Công cụ kiểm thử API | F24: Gửi yêu cầu và kiểm thử các API RESTful
A25: 2
A26: 3
A28: 2. Cấu trúc thư mục & Quyền truy cập / Directory Structure & Access Right
A30: Đường dẫn thư mục dự án/ Project Path: <Link Google Driver>
A31: Thư mục / Folder | D31: Mô tả / Description | E31: Phân quyền / Role
E32: PMO Project DirectorProject Advisor: Cố vấn dự án Project Assistant | F32: PD Product Manager Product Owner (PO) | G32: PM | H32: Game Designer | I32: QC | J32: QA | K32: Artist Game Artist Leader UI/UX Designer Concept Artist 2D Game Artist (Gồm 2 vị trí) 3D Game Artist (Gồm 1 vị trí) 3D Animator Sound Designer | L32: DEV Technical Director/Leader Unity Dev Backend Dev Tech Artist
A33: CONTROL | D33: Lưu trữ các tài liệu đã được duyệt / Store approved documents | E33: Trần Hải Trường Nguyễn Ngọc Diệu | F33: Nguyễn Ngọc Khánh Nguyễn Cao Hoàn Thanh | G33: Bùi Phúc Minh Tâm Nguyễn Đức Tú | H33: Nguyễn Thành Lộc Nguyễn Ngọc Thu Hằng Võ Trần Hạnh Nguyên | I33: Trần Thị Thanh Vân Bùi Thị Minh Thư Cao Thị Phương | J33: Đinh Thị Tố Loan Trần Kim Hương | K33: Hồ Quốc Phương Lương Tấn Trung Lê Hoàng Lan Vy | L33: Hà Duy Tuấn Nguyễn Văn Tá Ngô Trọng Hiếu Nguyễn Thành Đạt Đinh Thị Thủy Nguyễn Hoàng Linh
B34: Đội ngũ sản phẩm / Product Team | D34: Product Backlog, URD, SRS | E34: V | F34: V | G34: Full | H34: V | I34: V | J34: V | K34: X | L34: X
B35: Đội ngũ kiểm soát chất lượng / QA,QC team | D35: TestPlan, TestCase, Test scenario, Test Report | E35: V | F35: V | G35: Full | H35: V | I35: V | J35: V | K35: X | L35: X
B36: Đội ngũ thiết kế game / Game Design Team | D36: Game Concept Document Game Design Document Game Asset List Sound Design Document Localization text Game Tracking Document Game Balance Document | E36: V | F36: V | G36: Full | H36: V | I36: V | J36: V | K36: V | L36: V
B37: Đội ngũ nghệ thuật / Art team | D37: Design Asset | E37: V | F37: V | G37: Full | H37: V | I37: X | J37: V | K37: V | L37: V
B38: Đội ngũ âm thanh / Sound team | D38: Sound Asset | E38: V | F38: V | G38: Full | H38: V | I38: X | J38: V | K38: V | L38: V
B39: Đội ngũ phát triển / Developer team | D39: Source chương trình cài đặt cho khách hàng / Source installation program for clients UM. IM | E39: V | F39: V | G39: Full | H39: V | I39: V | J39: V | K39: V | L39: V
B40: Triển khai / Deployment | E40: V | F40: V | G40: Full | H40: V | I40: V | J40: V | K40: V | L40: V
B41: Tài liệu tham khảo / References | E41: V | F41: V | G41: Full | H41: V | I41: V | J41: V | K41: V | L41: V
B42: Quản lý dự án / Project Management | D42: Kế hoạch dự án, Kế hoạch chi tiết, Kế hoạch UAT, Kế hoạch Golive / Project Plan, Project Detail, UAT Plan, Golive Plan | E42: V | F42: V | G42: Full | H42: V | I42: X | J42: V | K42: X | L42: X
A43: WIP | D43: Lưu trữ các tài liệu đang soạn thảo / Archive documents in progress
B44: Đội ngũ sản phẩm / Product Team | D44: Product Backlog,URD, SRS | E44: V/C | F44: E Nguyễn Ngọc Khánh Nguyễn Cao Hoàn Thanh | G44: Full | H44: V | I44: V | J44: V | K44: X | L44: X
B45: Đội ngũ kiểm soát chất lượng / QA,QC team | D45: TestPlan, TestCase, Test scenario, Test Report | E45: V/C | F45: V/C | G45: Full | H45: V | I45: E Trần Thị Thanh Vân Bùi Thị Minh Thư Cao Thị Phương | J45: V | K45: X | L45: X
B46: Đội ngũ thiết kế game / Game Design Team | D46: Game Concept Document Game Design Document Game Asset List Sound Design Document Localization text Game Tracking Document Game Balance Document | E46: V/C | F46: V/C | G46: Full | H46: E Nguyễn Thành Lộc Nguyễn Ngọc Thu Hằng Võ Trần Hạnh Nguyên | I46: V | J46: V | K46: V | L46: V
...

Sheet Sheet6
B2: Project Director | C2: =COUNTIF('4.Resource'!$C$57:$C$89,B2) | D2: =SUMIF('4.Resource'!$C$57:$C$89,B2,'4.Resource'!$E$57:$E$89)
B3: Project Manager | C3: =COUNTIF('4.Resource'!$C$57:$C$89,B3) | D3: =SUMIF('4.Resource'!$C$57:$C$89,B3,'4.Resource'!$E$57:$E$89)
B4: Academic Advisor | C4: =COUNTIF('4.Resource'!$C$57:$C$89,B4) | D4: =SUMIF('4.Resource'!$C$57:$C$89,B4,'4.Resource'!$E$57:$E$89)
B5: Technical Advisor | C5: =COUNTIF('4.Resource'!$C$57:$C$89,B5) | D5: =SUMIF('4.Resource'!$C$57:$C$89,B5,'4.Resource'!$E$57:$E$89)
B6: Project Assistant | C6: =COUNTIF('4.Resource'!$C$57:$C$89,B6) | D6: =SUMIF('4.Resource'!$C$57:$C$89,B6,'4.Resource'!$E$57:$E$89)
B7: Project Assistant | C7: =COUNTIF('4.Resource'!$C$57:$C$89,B7) | D7: =SUMIF('4.Resource'!$C$57:$C$89,B7,'4.Resource'!$E$57:$E$89)
B8: Product Manager | C8: =COUNTIF('4.Resource'!$C$57:$C$89,B8) | D8: =SUMIF('4.Resource'!$C$57:$C$89,B8,'4.Resource'!$E$57:$E$89)
B9: Product Owner | C9: =COUNTIF('4.Resource'!$C$57:$C$89,B9) | D9: =SUMIF('4.Resource'!$C$57:$C$89,B9,'4.Resource'!$E$57:$E$89)
B10: Game Designer | C10: =COUNTIF('4.Resource'!$C$57:$C$89,B10) | D10: =SUMIF('4.Resource'!$C$57:$C$89,B10,'4.Resource'!$E$57:$E$89)
B11: Game Artist Leader | C11: =COUNTIF('4.Resource'!$C$57:$C$89,B11) | D11: =SUMIF('4.Resource'!$C$57:$C$89,B11,'4.Resource'!$E$57:$E$89)
B12: 2D Game Artist | C12: =COUNTIF('4.Resource'!$C$57:$C$89,B12) | D12: =SUMIF('4.Resource'!$C$57:$C$89,B12,'4.Resource'!$E$57:$E$89)
B13: UI/UX Designer | C13: =COUNTIF('4.Resource'!$C$57:$C$89,B13) | D13: =SUMIF('4.Resource'!$C$57:$C$89,B13,'4.Resource'!$E$57:$E$89)
... B24: Quality Control | C24: =COUNTIF('4.Resource'!$C$57:$C$89,B24) | D24: =SUMIF('4.Resource'!$C$57:$C$89,B24,'4.Resource'!$E$57:$E$89)

Sheet 7.Quality
C2: KẾ HOẠCH QUẢN LÝ CHẤT LƯỢNG/ QUALITY MANAGEMENT PLAN | G2: =ROC!F2
A4: Tiêu chí chất lượng/ Quality criteria
A6: # | B6: Metric Name | C6: Công thức / Formulas | D6: Đơn vị / Unit | E6: Thời gian / Time | F6: Mục tiêu / Target | G6: Notes
A7: 1 | B7: % Hiệu suất / % Effort Efficiency | C7: Tổng effort thực tế (MM)/ Tổng effort trên kế hoạch (MM) / Total Actual Effort (MM)/ Total Plan Effort (MM) | D7: % | E7: Kết thúc Sprint/Phase / End of Sprint/Phase | F7: <= 100% | G7: % Deviation (D): - Red: D >= 15% - Yellow: 5% < D < 15% - Green: D <= 5%
A8: 2 | B8: % Tiến độ / % _x0008_Progress | C8: Tổng số bài học đã hoàn thành/ Tổng số bài học trong kế hoạch / Total Completed Lessons/ Total Plan Lessons | D8: % | E8: Kết thúc Sprint/Phase / End of Sprint/Phase | F8: >= 100%
A9: 3 | B9: Năng suất / Productivity | C9: Tổng effort (MM)/ Tổng số bài đã hoàn thành / Total Effort (MM)/ Total Completed Lessons | D9: _x0008_No. | E9: Kết thúc Sprint/Phase / End of Sprint/Phase | F9: Actual < Plan
A10: 4 | B10: Sự hài lòng của khách hàng / Customer Satisfaction | C10: Điểm trung bình của khách hàng (Tối đa: 5, Tối thiểu: 1) / Average Points of Customer (Max: 5, Min: 1) | D10: Điểm / Point | E10: Kết thúc dự án / End of Project | F10: > 4 | G10: Green
A12: Các hoạt động khác/ Other activities
A14: Vui lòng lưu ý các hoạt động chất lượng khác mà khách hàng yêu cầu (nếu có) / Please note other quality activities that customer request (if any).
